Workbook

Sheet Leia primeiro
A1: Planilhas do Vem Trabalhar
A2: Versão 4, de 06/10/2026: entrevista do currículo, IA para o dono, comandos de voz e benchmark. Tudo que é pergunta é de tocar. Células amarelas com letra azul são suas.
A4: Em uma frase
A5: Um método só, do trabalhador autônomo até a empresa de mil funcionários: a mesma pessoa se cadastra, aprende, é avaliada com transparência e é encontrada pela vaga certa.
A7: Como os cursos funcionam
A8: Cursos nossos: só cursos livres, feitos por nós, com certificado de curso livre. Não usamos cursos de terceiros (Sebrae, Fundação Bradesco, Sistema S): ficaram de fora.
A9: Cursos técnicos e faculdades: entram por parceria. A escola paga ao Vem Trabalhar 50% da matrícula e 30% de cada mensalidade (como entendi sua fala; confirmar com cada escola).
A10: A comissão nunca muda a nota do match. O curso de parceiro aparece com a etiqueta 'Parceiro', para a pessoa saber que existe um acordo.
A12: O que tem em cada aba (toque no nome para ir)
A13: Parcerias | B13: Regra de comissão (50% da matrícula, 30% da mensalidade), calculadora e regras do acordo com escolas.
A14: Portal do parceiro | B14: O passo a passo da escola: cadastra a si, os cursos e as empresas; aparece ao aluno com a etiqueta Parceiro; comissão nasce da matrícula e das mensalidades.
A15: Escolas técnicas | B15: Lista de escolas técnicas parceiras, para você preencher: curso, matrícula, mensalidade, comissão por aluno, situação.
A16: Faculdades | B16: A mesma lista, para faculdades e universidades.
A17: Cursos com parceiros | B17: 31 cursos que queremos com escola parceira (técnicos e mistos), com quem emite o documento.
A18: Ideias de cursos | B18: 71 cursos livres nossos, com a atividade de toque de cada um. A meta de 200 se acompanha no topo.
A19: Cursos próprios | B19: Como é um curso nosso: lições curtas, atividade de toque, reteste, prova final, certificado.
A20: Canais | B20: 14 formas de entrar e de manter contato todo dia com as pessoas, com o que já pode rodar em 13/10.
A21: Sistema vivo | B21: Os agentes que propõem melhoria (benchmark, cursos, vídeos, match) e quem aprova.
A22: IA para o dono | B22: Os 3 pilares do texto da V4 (conteúdo em escala, análise de dados, imagens) e como cada um vira função, por voz ou foto, para cada dono que comprar o software.
A23: Comandos de voz | B23: 32 frases de exemplo: o dono, o gerente, o candidato e você falam, e o sistema faz, pedindo confirmação quando mexe com dinheiro.
A24: Benchmark | B24: O que vimos de novo no mercado e onde entra. O agente de benchmark acrescenta linhas; a coluna amarela é a sua decisão.
... A36: Fontes | B36: De onde vieram os testes.
A38: Mesmo método, qualquer tamanho de empresa
A39: Quem é | B39: O que vê na tela (proposta nossa) | C39: Plano por vagas por mês (decisão do GD, 06/10/2026)
A40: Quem trabalha sozinho (MEI, autônomo) | B40: Uma vaga de 1 toque, perfil pronto, cursos de gestão do pequeno negócio. | C40: 0 a 10 vagas: R$ 300
A41: Empresa com 2 a 50 funcionários | B41: As mesmas telas, com a vaga montada em 20 respostas de toque e a lista de candidatos já ordenada. | C41: 0 a 10 vagas: R$ 300; 11 a 500: R$ 500
A42: Empresa com 51 a 500 funcionários | B42: Acrescenta a avaliação de desempenho dos funcionários e os relatórios por setor. | C42: 11 a 500 vagas: R$ 500
A43: Empresa com 501 a 1.000 funcionários | B43: Acrescenta vários gestores, vários locais e relatórios por região. | C43: 501 a 1.000 vagas: R$ 1.000
A44: Mais de 1.000 | B44: Mesmo método, com contrato sob medida. | C44: Acima de 1.000 vagas: negociado
A45: Observação: o GD disse '11 a 50 = R$ 500' e '51 a 500 = R$ 500'; tratei como uma faixa só, de 11 a 500. O candidato paga R$ 80 (mensal ou uma vez: pergunta aberta). Semana de teste grátis, sem baixar nada.
A47: Regras que valem em tudo
A48: Ninguém é eliminado por nota ou por prova. A prova final de um curso só dá o certificado; quem não passa refaz com perguntas novas.
A49: A pessoa vê o que a empresa vê sobre ela e vê por que a nota deu aquele valor, com o curso que a faria subir.
A50: Dados sensíveis não entram no match: raça ou cor, religião, estado civil, filhos, gravidez, idade como filtro, saúde, orientação sexual, opinião política.
A51: Aviso de vaga, de curso e uso das respostas para estudo ou marketing só com consentimento separado, desmarcado de início e revogável.
A52: Funcionário sabe que está sendo avaliado e vê o próprio resultado. Avaliação serve para desenvolver, não para demitir de forma automática.
A53: Teste de jeito de ser e de interesses é para a pessoa se conhecer. Só vai para a empresa se ela autorizar, e nunca elimina.
A54: Certificado do Vem Trabalhar é de curso livre. Diploma técnico ou superior só instituição credenciada emite.
A55: Curso de parceiro leva a etiqueta 'Parceiro'. A comissão não entra na conta do match.
A56: O banco de pessoas só cresce com consentimento: nada de lista comprada, nada de raspar Instagram, nada de mensagem fora do aceite.
...

Sheet Parcerias
A1: Parcerias com escolas: como o Vem Trabalhar ganha
A2: A escola paga ao Vem Trabalhar uma comissão sobre cada aluno que trouxermos. Letra azul em fundo amarelo = você pode mudar.
A4: Regra | B4: Valor | C4: Observação
A5: Comissão sobre a matrícula | B5: 0.5 | C5: Como entendi sua fala: 50% da matrícula.
A6: Comissão sobre cada mensalidade | B6: 0.3 | C6: Como entendi sua fala: 30% da mensalidade.
A7: Quantas mensalidades pagam comissão | B7: 12 | C7: Premissa nossa (12). Pergunta aberta: vale por todas as mensalidades ou por um período?
A8: Quem paga | B8: A escola | C8: O aluno paga o preço normal da escola. A comissão sai da escola, não de um acréscimo ao aluno.
A10: Exemplo de conta (valores inventados) | B10: Valor | C10: Como calcula
A11: Matrícula (R$) | B11: 200 | C11: Exemplo
A12: Mensalidade (R$) | B12: 400 | C12: Exemplo
A13: Alunos que trouxemos | B13: 10 | C13: Exemplo
A14: Comissão por aluno (R$) | B14: =B11*B5+B12*B6*B7 -> 1540 | C14: matrícula x comissão da matrícula + mensalidade x comissão da mensalidade x número de mensalidades
A15: Receita do Vem Trabalhar com esses alunos (R$) | B15: =B14*B13 -> 15400 | C15: comissão por aluno x alunos
A17: Regras do acordo com escola
A18: Contrato por escola, revisado por advogado, dizendo quem paga, quando e como o Vem Trabalhar comprova que o aluno veio por nós.
A19: A escola precisa ser credenciada. Para faculdade, conferir no cadastro oficial do MEC (e-MEC); para escola técnica, no sistema de ensino do estado. Endereços e regras a confirmar.
A20: Curso de parceiro leva a etiqueta 'Parceiro'. A comissão nunca muda a nota do match nem a ordem das vagas.
A21: O diploma é da escola. O Vem Trabalhar nunca chama o próprio certificado de diploma.
A22: Meta de acompanhamento: quantos alunos por escola, quantos concluíram, quantos conseguiram vaga.

Sheet Portal do parceiro
A1: Portal do parceiro: a escola se cadastra e cadastra os próprios cursos e empresas
A2: Cada escola entra por um link, preenche tudo de toque e aparece para os alunos junto com os cursos livres, com a etiqueta 'Parceiro'.
A4: Etapa | B4: O que a escola faz | C4: O que o aluno vê | D4: Dado guardado | E4: Regra
A5: 1. Quero ser parceiro | B5: Entra por um link ou QR, informa nome, CNPJ, cidade, responsável e aceita o contrato. | C5: Nada ainda. | D5: Dados da instituição e aceite do contrato (data e versão). | E5: O aceite é do contrato revisado por advogado. Sem aceite, não publica nada.
A6: 2. Conferência | B6: Espera a conferência. | C6: Nada ainda. | D6: Situação: pendente, conferida ou recusada. | E6: Nós conferimos o credenciamento (faculdade: cadastro oficial do MEC; escola técnica: sistema de ensino do estado). Endereços e regras a confirmar.
A7: 3. Cadastrar curso | B7: Informa curso, tipo (técnico, graduação, curso livre pago), modalidade, CEP do local, duração, matrícula, mensalidade, vagas por turma, início e link de inscrição. | C7: Ficha do curso com preço, local, tempo de deslocamento e se é EAD ou presencial. | D7: Curso, preço, vagas, local (CEP) e data de início. | E7: Preço publicado é o preço normal da escola. O aluno não paga a mais por vir pelo Vem Trabalhar.
A8: 4. Cadastrar empresas | B8: Informa as empresas que contratam seus alunos (convênios de estágio e emprego) e as vagas que elas têm. | C8: As vagas aparecem no match, como as de qualquer empresa. | D8: Empresa e vaga ligadas à escola. | E8: A empresa precisa aceitar. As vagas seguem o mesmo método de 20 perguntas.
A9: 5. Publicar | B9: Toca em publicar. | C9: O curso aparece na tela de cursos, depois dos cursos livres que cobrem a mesma habilidade, com a etiqueta 'Parceiro'. | D9: Curso publicado, data e versão. | E9: A comissão nunca muda a nota do match nem a ordem.
A10: 6. Interesse do aluno | B10: Recebe o aviso de que alguém tem interesse (WhatsApp ou e-mail). | C10: Toca em 'Tenho interesse' e autoriza a escola a falar com ele. | D10: Interesse, consentimento do aluno, data e código de origem. | E10: Só vai para a escola quem tocou e autorizou. Nada de lista vendida.
A11: 7. Matrícula | B11: Marca 'matriculou' e anexa o comprovante. | C11: Confirma 'me matriculei' no app. | D11: Matrícula confirmada pelas duas pontas. | E11: A comissão da matrícula só nasce quando escola e aluno confirmam. Se houver divergência, a conta fica em análise.
A12: 8. Mensalidades | B12: Todo mês marca quem pagou ou envia a lista. | C12: Vê o curso na sua trilha. | D12: Mensalidade paga, por aluno e mês. | E12: A comissão da mensalidade nasce a cada mês pago. A escola aceita auditoria no contrato.
A13: 9. Extrato | B13: Vê o que deve, o que pagou e paga por Pix. | C13: - | D13: Comissões a receber e pagas, por escola, aluno e mês. | E13: Vencimento e multa por atraso ficam no contrato (advogado).

Sheet Escolas técnicas
A1: Escolas técnicas parceiras
A2: Primeira linha é um EXEMPLO inventado. Preencha as seguintes, uma escola por linha. Comissão por aluno é fórmula.
A4: Instituição | B4: Cidade e UF | C4: Curso | D4: Modalidade | E4: Matrícula (R$) | F4: Mensalidade (R$) | G4: Comissão sobre a matrícula | H4: Comissão sobre a mensalidade | I4: Comissão por aluno (R$) | J4: Credenciamento conferido? | K4: Contato | L4: Situação | M4: Observação
A5: EXEMPLO: Escola Técnica Modelo (inventada) | B5: Cidade Exemplo, UF | C5: Técnico em Eletrotécnica | D5: Presencial | E5: 300 | F5: 450 | G5: =Parcerias!$B$5 -> 0.5 | H5: =Parcerias!$B$6 -> 0.3 | I5: =IF(OR(E5="",F5=""),"",E5*G5+F5*H5*Parcerias!$B$7) -> 1770 | J5: Sim | K5: Pessoa Exemplo, (00) 00000-0000 | L5: Conversando | M5: Linha de exemplo; pode apagar.
A6: Centec (citado pelo GD) | C6: Elétrica, eletrônica, mecânica e mecânica de moto (citados pelo GD) | G6: =Parcerias!$B$5 -> 0.5 | H6: =Parcerias!$B$6 -> 0.3 | I6: =IF(OR(E6="",F6=""),"",E6*G6+F6*H6*Parcerias!$B$7) | L6: Não contatada | M6: Dados a confirmar: cidade, valores e credenciamento. Eu não abri o site.
G7: =Parcerias!$B$5 -> 0.5 | H7: =Parcerias!$B$6 -> 0.3 | I7: =IF(OR(E7="",F7=""),"",E7*G7+F7*H7*Parcerias!$B$7)
G8: =Parcerias!$B$5 -> 0.5 | H8: =Parcerias!$B$6 -> 0.3 | I8: =IF(OR(E8="",F8=""),"",E8*G8+F8*H8*Parcerias!$B$7)
G9: =Parcerias!$B$5 -> 0.5 | H9: =Parcerias!$B$6 -> 0.3 | I9: =IF(OR(E9="",F9=""),"",E9*G9+F9*H9*Parcerias!$B$7)
G10: =Parcerias!$B$5 -> 0.5 | H10: =Parcerias!$B$6 -> 0.3 | I10: =IF(OR(E10="",F10=""),"",E10*G10+F10*H10*Parcerias!$B$7)
G11: =Parcerias!$B$5 -> 0.5 | H11: =Parcerias!$B$6 -> 0.3 | I11: =IF(OR(E11="",F11=""),"",E11*G11+F11*H11*Parcerias!$B$7)
G12: =Parcerias!$B$5 -> 0.5 | H12: =Parcerias!$B$6 -> 0.3 | I12: =IF(OR(E12="",F12=""),"",E12*G12+F12*H12*Parcerias!$B$7)
G13: =Parcerias!$B$5 -> 0.5 | H13: =Parcerias!$B$6 -> 0.3 | I13: =IF(OR(E13="",F13=""),"",E13*G13+F13*H13*Parcerias!$B$7)
G14: =Parcerias!$B$5 -> 0.5 | H14: =Parcerias!$B$6 -> 0.3 | I14: =IF(OR(E14="",F14=""),"",E14*G14+F14*H14*Parcerias!$B$7)
G15: =Parcerias!$B$5 -> 0.5 | H15: =Parcerias!$B$6 -> 0.3 | I15: =IF(OR(E15="",F15=""),"",E15*G15+F15*H15*Parcerias!$B$7)
G16: =Parcerias!$B$5 -> 0.5 | H16: =Parcerias!$B$6 -> 0.3 | I16: =IF(OR(E16="",F16=""),"",E16*G16+F16*H16*Parcerias!$B$7)
G17: =Parcerias!$B$5 -> 0.5 | H17: =Parcerias!$B$6 -> 0.3 | I17: =IF(OR(E17="",F17=""),"",E17*G17+F17*H17*Parcerias!$B$7)
G18: =Parcerias!$B$5 -> 0.5 | H18: =Parcerias!$B$6 -> 0.3 | I18: =IF(OR(E18="",F18=""),"",E18*G18+F18*H18*Parcerias!$B$7)

Sheet Faculdades
A1: Faculdades e universidades parceiras
A2: Primeira linha é um EXEMPLO inventado. Preencha as seguintes, uma instituição por linha. Comissão por aluno é fórmula.
A4: Instituição | B4: Cidade e UF | C4: Curso | D4: Modalidade | E4: Matrícula (R$) | F4: Mensalidade (R$) | G4: Comissão sobre a matrícula | H4: Comissão sobre a mensalidade | I4: Comissão por aluno (R$) | J4: Credenciamento conferido? | K4: Contato | L4: Situação | M4: Observação
A5: EXEMPLO: Faculdade Modelo (inventada) | B5: Cidade Exemplo, UF | C5: Administração (graduação) | D5: EAD | E5: 250 | F5: 380 | G5: =Parcerias!$B$5 -> 0.5 | H5: =Parcerias!$B$6 -> 0.3 | I5: =IF(OR(E5="",F5=""),"",E5*G5+F5*H5*Parcerias!$B$7) -> 1493 | J5: Sim | K5: Pessoa Exemplo, (00) 00000-0000 | L5: Proposta enviada | M5: Linha de exemplo; pode apagar.
G6: =Parcerias!$B$5 -> 0.5 | H6: =Parcerias!$B$6 -> 0.3 | I6: =IF(OR(E6="",F6=""),"",E6*G6+F6*H6*Parcerias!$B$7)
G7: =Parcerias!$B$5 -> 0.5 | H7: =Parcerias!$B$6 -> 0.3 | I7: =IF(OR(E7="",F7=""),"",E7*G7+F7*H7*Parcerias!$B$7)
G8: =Parcerias!$B$5 -> 0.5 | H8: =Parcerias!$B$6 -> 0.3 | I8: =IF(OR(E8="",F8=""),"",E8*G8+F8*H8*Parcerias!$B$7)
G9: =Parcerias!$B$5 -> 0.5 | H9: =Parcerias!$B$6 -> 0.3 | I9: =IF(OR(E9="",F9=""),"",E9*G9+F9*H9*Parcerias!$B$7)
G10: =Parcerias!$B$5 -> 0.5 | H10: =Parcerias!$B$6 -> 0.3 | I10: =IF(OR(E10="",F10=""),"",E10*G10+F10*H10*Parcerias!$B$7)
G11: =Parcerias!$B$5 -> 0.5 | H11: =Parcerias!$B$6 -> 0.3 | I11: =IF(OR(E11="",F11=""),"",E11*G11+F11*H11*Parcerias!$B$7)
G12: =Parcerias!$B$5 -> 0.5 | H12: =Parcerias!$B$6 -> 0.3 | I12: =IF(OR(E12="",F12=""),"",E12*G12+F12*H12*Parcerias!$B$7)
G13: =Parcerias!$B$5 -> 0.5 | H13: =Parcerias!$B$6 -> 0.3 | I13: =IF(OR(E13="",F13=""),"",E13*G13+F13*H13*Parcerias!$B$7)
G14: =Parcerias!$B$5 -> 0.5 | H14: =Parcerias!$B$6 -> 0.3 | I14: =IF(OR(E14="",F14=""),"",E14*G14+F14*H14*Parcerias!$B$7)
G15: =Parcerias!$B$5 -> 0.5 | H15: =Parcerias!$B$6 -> 0.3 | I15: =IF(OR(E15="",F15=""),"",E15*G15+F15*H15*Parcerias!$B$7)
G16: =Parcerias!$B$5 -> 0.5 | H16: =Parcerias!$B$6 -> 0.3 | I16: =IF(OR(E16="",F16=""),"",E16*G16+F16*H16*Parcerias!$B$7)
G17: =Parcerias!$B$5 -> 0.5 | H17: =Parcerias!$B$6 -> 0.3 | I17: =IF(OR(E17="",F17=""),"",E17*G17+F17*H17*Parcerias!$B$7)

Sheet Cursos com parceiros
A1: Cursos que queremos com escola parceira
A2: Técnicos (diploma da escola) e mistos (teoria nossa, prática com parceiro). Coloque o parceiro na coluna amarela quando houver.
A4: Nº | B4: Setor | C4: Curso | D4: Tipo | E4: Horas-alvo | F4: Quem emite o documento | G4: Parceiro | H4: Situação
A5: 1 | B5: Gestão e carreira | C5: Libras básico | D5: Misto (teoria nossa, prática com parceiro) | E5: 10 | F5: Vem Trabalhar (certificado) + parceiro confirma a prática | H5: Sem parceiro
A6: 2 | B6: Turismo e gastronomia | C6: Auxiliar de cozinha | D6: Misto (teoria nossa, prática com parceiro) | E6: 20 | F6: Vem Trabalhar (certificado) + parceiro confirma a prática | H6: Sem parceiro
A7: 3 | B7: Turismo e gastronomia | C7: Barista | D7: Misto (teoria nossa, prática com parceiro) | E7: 8 | F7: Vem Trabalhar (certificado) + parceiro confirma a prática | H7: Sem parceiro
A8: 4 | B8: Turismo e gastronomia | C8: Padaria e confeitaria básica | D8: Misto (teoria nossa, prática com parceiro) | E8: 20 | F8: Vem Trabalhar (certificado) + parceiro confirma a prática | H8: Sem parceiro
A9: 5 | B9: Turismo e gastronomia | C9: Pizzaiolo e churrasqueiro | D9: Misto (teoria nossa, prática com parceiro) | E9: 20 | F9: Vem Trabalhar (certificado) + parceiro confirma a prática | H9: Sem parceiro
A10: 6 | B10: Turismo e gastronomia | C10: Bartender | D10: Misto (teoria nossa, prática com parceiro) | E10: 12 | F10: Vem Trabalhar (certificado) + parceiro confirma a prática | H10: Sem parceiro
A11: 7 | B11: Indústria | C11: Metrologia básica (paquímetro e micrômetro) | D11: Misto (teoria nossa, prática com parceiro) | E11: 10 | F11: Vem Trabalhar (certificado) + parceiro confirma a prática | H11: Sem parceiro
A12: 8 | B12: Indústria | C12: Operador de empilhadeira | D12: Técnico (escola parceira) | E12: 40 | F12: Escola credenciada (diploma técnico) | H12: Sem parceiro
A13: 9 | B13: Indústria | C13: Eletricista (curso técnico) | D13: Técnico (escola parceira) | E13: escola define | F13: Escola credenciada (diploma técnico) | H13: Sem parceiro
A14: 10 | B14: Indústria | C14: Eletrônica (curso técnico) | D14: Técnico (escola parceira) | E14: escola define | F14: Escola credenciada (diploma técnico) | H14: Sem parceiro
A15: 11 | B15: Indústria | C15: Mecânica de motos | D15: Técnico (escola parceira) | E15: escola define | F15: Escola credenciada (diploma técnico) | H15: Sem parceiro
A16: 12 | B16: Indústria | C16: Mecânica automotiva básica | D16: Técnico (escola parceira) | E16: escola define | F16: Escola credenciada (diploma técnico) | H16: Sem parceiro
A17: 13 | B17: Indústria | C17: Soldagem | D17: Técnico (escola parceira) | E17: escola define | F17: Escola credenciada (diploma técnico) | H17: Sem parceiro
A18: 14 | B18: Indústria | C18: Manutenção industrial | D18: Técnico (escola parceira) | E18: escola define | F18: Escola credenciada (diploma técnico) | H18: Sem parceiro
A19: 15 | B19: Indústria | C19: Operador de máquinas CNC | D19: Técnico (escola parceira) | E19: escola define | F19: Escola credenciada (diploma técnico) | H19: Sem parceiro
A20: 16 | B20: Indústria | C20: Costura industrial | D20: Misto (teoria nossa, prática com parceiro) | E20: 30 | F20: Vem Trabalhar (certificado) + parceiro confirma a prática | H20: Sem parceiro
A21: 17 | B21: Saúde e cuidados | C21: Técnico de enfermagem | D21: Técnico (escola parceira) | E21: escola define | F21: Escola credenciada (diploma técnico) | H21: Sem parceiro
A22: 18 | B22: Saúde e cuidados | C22: Técnico em saúde bucal | D22: Técnico (escola parceira) | E22: escola define | F22: Escola credenciada (diploma técnico) | H22: Sem parceiro
A23: 19 | B23: Saúde e cuidados | C23: Atendente de farmácia | D23: Técnico (escola parceira) | E23: escola define | F23: Escola credenciada (diploma técnico) | H23: Sem parceiro
A24: 20 | B24: Saúde e cuidados | C24: Cuidador de idosos | D24: Misto (teoria nossa, prática com parceiro) | E24: 40 | F24: Vem Trabalhar (certificado) + parceiro confirma a prática | H24: Sem parceiro
A25: 21 | B25: Saúde e cuidados | C25: Primeiros socorros no trabalho | D25: Misto (teoria nossa, prática com parceiro) | E25: 8 | F25: Vem Trabalhar (certificado) + parceiro confirma a prática | H25: Sem parceiro
A26: 22 | B26: Agro | C26: Apicultura básica | D26: Misto (teoria nossa, prática com parceiro) | E26: 12 | F26: Vem Trabalhar (certificado) + parceiro confirma a prática | H26: Sem parceiro
A27: 23 | B27: Agro | C27: Piscicultura básica | D27: Misto (teoria nossa, prática com parceiro) | E27: 12 | F27: Vem Trabalhar (certificado) + parceiro confirma a prática | H27: Sem parceiro
A28: 24 | B28: Agro | C28: Agroindústria artesanal (queijo, doces) | D28: Misto (teoria nossa, prática com parceiro) | E28: 12 | F28: Vem Trabalhar (certificado) + parceiro confirma a prática | H28: Sem parceiro
A29: 25 | B29: Agro | C29: Operador de máquinas agrícolas | D29: Técnico (escola parceira) | E29: escola define | F29: Escola credenciada (diploma técnico) | H29: Sem parceiro
A30: 26 | B30: Construção | C30: Pintura de parede | D30: Misto (teoria nossa, prática com parceiro) | E30: 12 | F30: Vem Trabalhar (certificado) + parceiro confirma a prática | H30: Sem parceiro
A31: 27 | B31: Construção | C31: Instalação hidráulica básica | D31: Misto (teoria nossa, prática com parceiro) | E31: 20 | F31: Vem Trabalhar (certificado) + parceiro confirma a prática | H31: Sem parceiro
A32: 28 | B32: Construção | C32: Eletricista predial | D32: Técnico (escola parceira) | E32: escola define | F32: Escola credenciada (diploma técnico) | H32: Sem parceiro
A33: 29 | B33: Construção | C33: Pedreiro de acabamento | D33: Misto (teoria nossa, prática com parceiro) | E33: 40 | F33: Vem Trabalhar (certificado) + parceiro confirma a prática | H33: Sem parceiro
A34: 30 | B34: Técnico e tecnologia | C34: Suporte técnico em informática | D34: Misto (teoria nossa, prática com parceiro) | E34: 20 | F34: Vem Trabalhar (certificado) + parceiro confirma a prática | H34: Sem parceiro
A35: 31 | B35: Técnico e tecnologia | C35: Redes de computadores (curso técnico) | D35: Técnico (escola parceira) | E35: escola define | F35: Escola credenciada (diploma técnico) | H35: Sem parceiro

Sheet Ideias de cursos
A1: Cursos livres nossos: ideias
A2: Só cursos livres, feitos por nós, com certificado de curso livre. As colunas das regiões leem a aba Prioridade. Técnicos e mistos estão na aba Cursos com parceiros.
B3: Ideias de cursos livres | C3: =COUNTA(C8:C300) -> 71
B4: Meta de cursos | C4: 200
B5: Falta para a meta (parcerias somam por fora) | C5: =MAX(0,C4-C3) -> 129
A7: Nº | B7: Setor | C7: Curso | D7: Horas-alvo | E7: Atividade de toque | F7: Norte | G7: Nordeste | H7: Centro-Oeste | I7: Sudeste | J7: Sul
A8: 1 | B8: Comércio e serviços | C8: Atendimento de balcão | D8: 6 | E8: Simulador: escolha a resposta ao cliente | F8: =INDEX(Prioridade!$B$5:$J$9,MATCH(F$7,Prioridade!$A$5:$A$9,0),MATCH($B8,Prioridade!$B$4:$J$4,0)) -> Média | G8: =INDEX(Prioridade!$B$5:$J$9,MATCH(G$7,Prioridade!$A$5:$A$9,0),MATCH($B8,Prioridade!$B$4:$J$4,0)) -> Alta | H8: =INDEX(Prioridade!$B$5:$J$9,MATCH(H$7,Prioridade!$A$5:$A$9,0),MATCH($B8,Prioridade!$B$4:$J$4,0)) -> Média | I8: =INDEX(Prioridade!$B$5:$J$9,MATCH(I$7,Prioridade!$A$5:$A$9,0),MATCH($B8,Prioridade!$B$4:$J$4,0)) -> Alta | J8: =INDEX(Prioridade!$B$5:$J$9,MATCH(J$7,Prioridade!$A$5:$A$9,0),MATCH($B8,Prioridade!$B$4:$J$4,0)) -> Média
A9: 2 | B9: Comércio e serviços | C9: Operador de caixa | D9: 8 | E9: Contar o troco arrastando notas e moedas | F9: =INDEX(Prioridade!$B$5:$J$9,MATCH(F$7,Prioridade!$A$5:$A$9,0),MATCH($B9,Prioridade!$B$4:$J$4,0)) -> Média | G9: =INDEX(Prioridade!$B$5:$J$9,MATCH(G$7,Prioridade!$A$5:$A$9,0),MATCH($B9,Prioridade!$B$4:$J$4,0)) -> Alta | H9: =INDEX(Prioridade!$B$5:$J$9,MATCH(H$7,Prioridade!$A$5:$A$9,0),MATCH($B9,Prioridade!$B$4:$J$4,0)) -> Média | I9: =INDEX(Prioridade!$B$5:$J$9,MATCH(I$7,Prioridade!$A$5:$A$9,0),MATCH($B9,Prioridade!$B$4:$J$4,0)) -> Alta | J9: =INDEX(Prioridade!$B$5:$J$9,MATCH(J$7,Prioridade!$A$5:$A$9,0),MATCH($B9,Prioridade!$B$4:$J$4,0)) -> Média
A10: 3 | B10: Comércio e serviços | C10: Atendimento ao cliente por WhatsApp | D10: 4 | E10: Ordenar mensagens e escolher o tom | F10: =INDEX(Prioridade!$B$5:$J$9,MATCH(F$7,Prioridade!$A$5:$A$9,0),MATCH($B10,Prioridade!$B$4:$J$4,0)) -> Média | G10: =INDEX(Prioridade!$B$5:$J$9,MATCH(G$7,Prioridade!$A$5:$A$9,0),MATCH($B10,Prioridade!$B$4:$J$4,0)) -> Alta | H10: =INDEX(Prioridade!$B$5:$J$9,MATCH(H$7,Prioridade!$A$5:$A$9,0),MATCH($B10,Prioridade!$B$4:$J$4,0)) -> Média | I10: =INDEX(Prioridade!$B$5:$J$9,MATCH(I$7,Prioridade!$A$5:$A$9,0),MATCH($B10,Prioridade!$B$4:$J$4,0)) -> Alta | J10: =INDEX(Prioridade!$B$5:$J$9,MATCH(J$7,Prioridade!$A$5:$A$9,0),MATCH($B10,Prioridade!$B$4:$J$4,0)) -> Média
A11: 4 | B11: Comércio e serviços | C11: Vendas para quem está começando | D11: 8 | E11: Role-play: contornar uma objeção | F11: =INDEX(Prioridade!$B$5:$J$9,MATCH(F$7,Prioridade!$A$5:$A$9,0),MATCH($B11,Prioridade!$B$4:$J$4,0)) -> Média | G11: =INDEX(Prioridade!$B$5:$J$9,MATCH(G$7,Prioridade!$A$5:$A$9,0),MATCH($B11,Prioridade!$B$4:$J$4,0)) -> Alta | H11: =INDEX(Prioridade!$B$5:$J$9,MATCH(H$7,Prioridade!$A$5:$A$9,0),MATCH($B11,Prioridade!$B$4:$J$4,0)) -> Média | I11: =INDEX(Prioridade!$B$5:$J$9,MATCH(I$7,Prioridade!$A$5:$A$9,0),MATCH($B11,Prioridade!$B$4:$J$4,0)) -> Alta | J11: =INDEX(Prioridade!$B$5:$J$9,MATCH(J$7,Prioridade!$A$5:$A$9,0),MATCH($B11,Prioridade!$B$4:$J$4,0)) -> Média
A12: 5 | B12: Comércio e serviços | C12: Atendimento por telefone | D12: 4 | E12: Escolher a frase certa em cada ligação | F12: =INDEX(Prioridade!$B$5:$J$9,MATCH(F$7,Prioridade!$A$5:$A$9,0),MATCH($B12,Prioridade!$B$4:$J$4,0)) -> Média | G12: =INDEX(Prioridade!$B$5:$J$9,MATCH(G$7,Prioridade!$A$5:$A$9,0),MATCH($B12,Prioridade!$B$4:$J$4,0)) -> Alta | H12: =INDEX(Prioridade!$B$5:$J$9,MATCH(H$7,Prioridade!$A$5:$A$9,0),MATCH($B12,Prioridade!$B$4:$J$4,0)) -> Média | I12: =INDEX(Prioridade!$B$5:$J$9,MATCH(I$7,Prioridade!$A$5:$A$9,0),MATCH($B12,Prioridade!$B$4:$J$4,0)) -> Alta | J12: =INDEX(Prioridade!$B$5:$J$9,MATCH(J$7,Prioridade!$A$5:$A$9,0),MATCH($B12,Prioridade!$B$4:$J$4,0)) -> Média
A13: 6 | B13: Comércio e serviços | C13: Como lidar com cliente difícil | D13: 3 | E13: Escolher o caminho em histórias curtas | F13: =INDEX(Prioridade!$B$5:$J$9,MATCH(F$7,Prioridade!$A$5:$A$9,0),MATCH($B13,Prioridade!$B$4:$J$4,0)) -> Média | G13: =INDEX(Prioridade!$B$5:$J$9,MATCH(G$7,Prioridade!$A$5:$A$9,0),MATCH($B13,Prioridade!$B$4:$J$4,0)) -> Alta | H13: =INDEX(Prioridade!$B$5:$J$9,MATCH(H$7,Prioridade!$A$5:$A$9,0),MATCH($B13,Prioridade!$B$4:$J$4,0)) -> Média | I13: =INDEX(Prioridade!$B$5:$J$9,MATCH(I$7,Prioridade!$A$5:$A$9,0),MATCH($B13,Prioridade!$B$4:$J$4,0)) -> Alta | J13: =INDEX(Prioridade!$B$5:$J$9,MATCH(J$7,Prioridade!$A$5:$A$9,0),MATCH($B13,Prioridade!$B$4:$J$4,0)) -> Média
A14: 7 | B14: Comércio e serviços | C14: Organização e reposição de loja | D14: 5 | E14: Arrastar produtos para a prateleira certa | F14: =INDEX(Prioridade!$B$5:$J$9,MATCH(F$7,Prioridade!$A$5:$A$9,0),MATCH($B14,Prioridade!$B$4:$J$4,0)) -> Média | G14: =INDEX(Prioridade!$B$5:$J$9,MATCH(G$7,Prioridade!$A$5:$A$9,0),MATCH($B14,Prioridade!$B$4:$J$4,0)) -> Alta | H14: =INDEX(Prioridade!$B$5:$J$9,MATCH(H$7,Prioridade!$A$5:$A$9,0),MATCH($B14,Prioridade!$B$4:$J$4,0)) -> Média | I14: =INDEX(Prioridade!$B$5:$J$9,MATCH(I$7,Prioridade!$A$5:$A$9,0),MATCH($B14,Prioridade!$B$4:$J$4,0)) -> Alta | J14: =INDEX(Prioridade!$B$5:$J$9,MATCH(J$7,Prioridade!$A$5:$A$9,0),MATCH($B14,Prioridade!$B$4:$J$4,0)) -> Média
A15: 8 | B15: Comércio e serviços | C15: Controle de estoque simples | D15: 6 | E15: Contar e conferir a lista | F15: =INDEX(Prioridade!$B$5:$J$9,MATCH(F$7,Prioridade!$A$5:$A$9,0),MATCH($B15,Prioridade!$B$4:$J$4,0)) -> Média | G15: =INDEX(Prioridade!$B$5:$J$9,MATCH(G$7,Prioridade!$A$5:$A$9,0),MATCH($B15,Prioridade!$B$4:$J$4,0)) -> Alta | H15: =INDEX(Prioridade!$B$5:$J$9,MATCH(H$7,Prioridade!$A$5:$A$9,0),MATCH($B15,Prioridade!$B$4:$J$4,0)) -> Média | I15: =INDEX(Prioridade!$B$5:$J$9,MATCH(I$7,Prioridade!$A$5:$A$9,0),MATCH($B15,Prioridade!$B$4:$J$4,0)) -> Alta | J15: =INDEX(Prioridade!$B$5:$J$9,MATCH(J$7,Prioridade!$A$5:$A$9,0),MATCH($B15,Prioridade!$B$4:$J$4,0)) -> Média
A16: 9 | B16: Comércio e serviços | C16: Vender pelas redes sociais | D16: 6 | E16: Montar uma postagem de venda | F16: =INDEX(Prioridade!$B$5:$J$9,MATCH(F$7,Prioridade!$A$5:$A$9,0),MATCH($B16,Prioridade!$B$4:$J$4,0)) -> Média | G16: =INDEX(Prioridade!$B$5:$J$9,MATCH(G$7,Prioridade!$A$5:$A$9,0),MATCH($B16,Prioridade!$B$4:$J$4,0)) -> Alta | H16: =INDEX(Prioridade!$B$5:$J$9,MATCH(H$7,Prioridade!$A$5:$A$9,0),MATCH($B16,Prioridade!$B$4:$J$4,0)) -> Média | I16: =INDEX(Prioridade!$B$5:$J$9,MATCH(I$7,Prioridade!$A$5:$A$9,0),MATCH($B16,Prioridade!$B$4:$J$4,0)) -> Alta | J16: =INDEX(Prioridade!$B$5:$J$9,MATCH(J$7,Prioridade!$A$5:$A$9,0),MATCH($B16,Prioridade!$B$4:$J$4,0)) -> Média
A17: 10 | B17: Comércio e serviços | C17: Foto de produto com o celular | D17: 4 | E17: Comparar fotos boas e ruins | F17: =INDEX(Prioridade!$B$5:$J$9,MATCH(F$7,Prioridade!$A$5:$A$9,0),MATCH($B17,Prioridade!$B$4:$J$4,0)) -> Média | G17: =INDEX(Prioridade!$B$5:$J$9,MATCH(G$7,Prioridade!$A$5:$A$9,0),MATCH($B17,Prioridade!$B$4:$J$4,0)) -> Alta | H17: =INDEX(Prioridade!$B$5:$J$9,MATCH(H$7,Prioridade!$A$5:$A$9,0),MATCH($B17,Prioridade!$B$4:$J$4,0)) -> Média | I17: =INDEX(Prioridade!$B$5:$J$9,MATCH(I$7,Prioridade!$A$5:$A$9,0),MATCH($B17,Prioridade!$B$4:$J$4,0)) -> Alta | J17: =INDEX(Prioridade!$B$5:$J$9,MATCH(J$7,Prioridade!$A$5:$A$9,0),MATCH($B17,Prioridade!$B$4:$J$4,0)) -> Média
A18: 11 | B18: Comércio e serviços | C18: Marketing e publicidade para pequenos negócios | D18: 10 | E18: Montar uma campanha em 3 passos | F18: =INDEX(Prioridade!$B$5:$J$9,MATCH(F$7,Prioridade!$A$5:$A$9,0),MATCH($B18,Prioridade!$B$4:$J$4,0)) -> Média | G18: =INDEX(Prioridade!$B$5:$J$9,MATCH(G$7,Prioridade!$A$5:$A$9,0),MATCH($B18,Prioridade!$B$4:$J$4,0)) -> Alta | H18: =INDEX(Prioridade!$B$5:$J$9,MATCH(H$7,Prioridade!$A$5:$A$9,0),MATCH($B18,Prioridade!$B$4:$J$4,0)) -> Média | I18: =INDEX(Prioridade!$B$5:$J$9,MATCH(I$7,Prioridade!$A$5:$A$9,0),MATCH($B18,Prioridade!$B$4:$J$4,0)) -> Alta | J18: =INDEX(Prioridade!$B$5:$J$9,MATCH(J$7,Prioridade!$A$5:$A$9,0),MATCH($B18,Prioridade!$B$4:$J$4,0)) -> Média
A19: 12 | B19: Comércio e serviços | C19: Instagram para negócios | D19: 6 | E19: Escolher legenda e horário | F19: =INDEX(Prioridade!$B$5:$J$9,MATCH(F$7,Prioridade!$A$5:$A$9,0),MATCH($B19,Prioridade!$B$4:$J$4,0)) -> Média | G19: =INDEX(Prioridade!$B$5:$J$9,MATCH(G$7,Prioridade!$A$5:$A$9,0),MATCH($B19,Prioridade!$B$4:$J$4,0)) -> Alta | H19: =INDEX(Prioridade!$B$5:$J$9,MATCH(H$7,Prioridade!$A$5:$A$9,0),MATCH($B19,Prioridade!$B$4:$J$4,0)) -> Média | I19: =INDEX(Prioridade!$B$5:$J$9,MATCH(I$7,Prioridade!$A$5:$A$9,0),MATCH($B19,Prioridade!$B$4:$J$4,0)) -> Alta | J19: =INDEX(Prioridade!$B$5:$J$9,MATCH(J$7,Prioridade!$A$5:$A$9,0),MATCH($B19,Prioridade!$B$4:$J$4,0)) -> Média
... A78: 71 | B78: Técnico e tecnologia | C78: Criação de site simples | D78: 10 | E78: Montar uma página arrastando blocos | F78: =INDEX(Prioridade!$B$5:$J$9,MATCH(F$7,Prioridade!$A$5:$A$9,0),MATCH($B78,Prioridade!$B$4:$J$4,0)) -> Alta | G78: =INDEX(Prioridade!$B$5:$J$9,MATCH(G$7,Prioridade!$A$5:$A$9,0),MATCH($B78,Prioridade!$B$4:$J$4,0)) -> Média | H78: =INDEX(Prioridade!$B$5:$J$9,MATCH(H$7,Prioridade!$A$5:$A$9,0),MATCH($B78,Prioridade!$B$4:$J$4,0)) -> Média | I78: =INDEX(Prioridade!$B$5:$J$9,MATCH(I$7,Prioridade!$A$5:$A$9,0),MATCH($B78,Prioridade!$B$4:$J$4,0)) -> Alta | J78: =INDEX(Prioridade!$B$5:$J$9,MATCH(J$7,Prioridade!$A$5:$A$9,0),MATCH($B78,Prioridade!$B$4:$J$4,0)) -> Alta

Sheet Cursos próprios
A1: Como é um curso do Vem Trabalhar
A2: Curso livre feito por nós, com lições curtas, atividades de toque, reteste e prova final que dá certificado e nunca elimina.
A4: Parte | B4: Como é
A5: Tamanho | B5: De 3 a 20 horas por curso, em lições de 5 a 8 minutos. Cabe numa pausa e no 3G.
A6: Cada lição | B6: 1) texto curto (até 150 palavras) com figura; 2) áudio opcional com voz calma; 3) atividade de toque (arrastar, ordenar, escolher a resposta do cliente, contar o troco); 4) mini-pergunta.
A7: Reteste | B7: Perguntas que já erradas voltam em outro dia, com outra redação. Cada habilidade tem pelo menos 3 perguntas diferentes no banco.
A8: Prova final | B8: 10 a 20 perguntas sorteadas do banco. Nota mínima 70%. Pode refazer quantas vezes quiser, com perguntas novas. Nunca elimina ninguém.
A9: Certificado | B9: Certificado de conclusão de curso livre, em PDF, com código e QR para a empresa conferir. Não é diploma. Diploma técnico só uma escola credenciada pode emitir.
A10: Quem escreve | B10: A IA escreve o rascunho; uma pessoa revisa antes de publicar (conteúdo errado em curso é risco para nós).
A11: Melhoria contínua | B11: O app mede onde as pessoas erram e saem; a pergunta mais errada vira lição melhor. Cada curso tem versão e data da revisão.
A12: Funciona em rede ruim | B12: Lição baixa em poucos KB, texto primeiro, imagem leve, áudio só se a pessoa tocar. Continua de onde parou.
A13: Liga com o match | B13: Cada curso concluído soma habilidade e certificado no perfil. Na vaga, o app mostra: 'faça este curso e sua nota sobe de 62% para 74%'.
A14: O que não substitui | B14: Treinamentos que a lei exige de instituição credenciada (NR com carga e instrutor, CNH, cursos de conselhos como COREN) e curso técnico com diploma.

Sheet Canais
A1: Banco de pessoas vivo: 14 formas de entrar e de manter contato todo dia
A2: Regra de ouro: o banco só cresce com consentimento. Nada de lista comprada, nada de raspar Instagram. Custos a verificar antes de decidir.
A4: Nº | B4: Canal | C4: Como a pessoa entra no banco | D4: O que ela recebe ou faz todo dia | E4: Consentimento | F4: Custo (a verificar) | G4: Precisa de código? | H4: Pronto para 13/10? | I4: Cuidado
A5: 1 | B5: QR e link nos restaurantes do Vem Comer | C5: Cartaz na mesa e no balcão: 'Procura emprego? Toque aqui'. | D5: Vaga perto de onde a pessoa está. | E5: No cadastro, com caixa desmarcada. | F5: Impressão do cartaz | G5: Pouco | H5: Sim | I5: Só pôr o cartaz onde o dono do restaurante aceitar.
A6: 2 | B6: Link na bio e posts das páginas de vagas do Instagram | C6: Páginas parceiras (as mais de mil que o GD conhece) divulgam o link: 'Candidate-se com 1 toque'. | D6: Stories, posts e vagas novas. | E6: No cadastro. | F6: Acordo com cada página (permuta ou pagamento) | G6: Pouco | H6: Sim | I6: Não raspar dados do Instagram nem usar robô: a regra da rede proíbe. Só link.
A7: 3 | B7: WhatsApp: link de entrada e lista com aceite | C7: Toque em 'falar no WhatsApp' abre a conversa; a pessoa diz 'quero receber vagas'. | D7: Vagas novas, lição do dia, aviso de entrevista. | E7: Aceite escrito na conversa (opt-in). | F7: Verificar: a conta oficial cobra por mensagem enviada | G7: Pouco (entrada); muito (envio em massa) | H7: Parcial | I7: Usar só a conta oficial do WhatsApp; mensagem fora do aceite é bloqueio.
A8: 4 | B8: Notificação do app (PWA) | C8: A pessoa abre o app no celular e aceita receber avisos. | D8: Vaga com nota alta, lição do dia, prazo de curso. | E8: Permissão do próprio celular. | F8: Perto de zero | G8: Médio | H8: Não | I8: No iPhone o aviso só funciona com o app instalado na tela inicial (verificar a versão).
A9: 5 | B9: E-mail | C9: A pessoa informa o e-mail no cadastro. | D9: Resumo semanal de vagas e cursos. | E9: Caixa de aceite separada, com cancelamento em um toque. | F9: Baixo (verificar) | G9: Pouco | H9: Parcial | I9: Todo e-mail precisa de link para sair da lista.
A10: 6 | B10: SMS | C10: Código de entrada no cadastro. | D10: Código e aviso urgente (entrevista marcada). | E10: Aceite no cadastro. | F10: Por mensagem (verificar) | G10: Médio | H10: Não | I10: Só para o que é urgente; custa por mensagem.
A11: 7 | B11: Currículo em PDF com link e QR | C11: Cada currículo compartilhado leva 'Feito no Vem Trabalhar'. | D11: Quem recebe o currículo conhece o app. | E11: Quem abre o link se cadastra por conta própria. | F11: Perto de zero | G11: Muito | H11: Não | I11: A marca fica discreta e pode ser desligada num plano pago.
A12: 8 | B12: Indique um amigo | C12: Link de convite com código. | D12: Avisos de quando o amigo entra. | E12: O amigo aceita ao se cadastrar. | F12: Prêmio a definir | G12: Médio | H12: Não | I12: Prêmio em curso ou recurso do app, não em dinheiro, até o advogado ver.
A13: 9 | B13: Páginas públicas de vagas e cursos (Google) | C13: Busca no Google leva à vaga ou ao curso. | D13: - | E13: No cadastro. | F13: Perto de zero depois de pronto | G13: Muito | H13: Não | I13: Verificar se o Google exibe vagas no Brasil com esse tipo de marcação.
A14: 10 | B14: Lição do dia e sequência de dias | C14: Quem faz um curso livre ganha uma lição curta por dia. | D14: Uma lição de 5 a 8 minutos, com sequência de dias seguidos. | E14: Aceite de avisos. | F14: Perto de zero | G14: Muito | H14: Não | I14: A sequência incentiva o hábito, mas não pune a pessoa que falha.
A15: 11 | B15: Parceiros convidam alunos e ex-alunos | C15: Escola envia o link pelo portal do parceiro. | D15: Cursos e vagas ligadas ao curso dela. | E15: O aluno aceita ao se cadastrar. | F15: Zero (a escola faz) | G15: Médio | H15: Parcial | I15: Escola não envia lista de contatos para nós: o aluno entra pelo link.
A16: 12 | B16: Empresas convidam funcionários e candidatos | C16: Empresa envia o link para a equipe e para quem recebeu a vaga. | D16: Avaliação, cursos e vagas internas. | E16: O funcionário aceita e sabe que será avaliado. | F16: Zero (a empresa faz) | G16: Médio | H16: Não | I16: Funcionário vê o resultado dele; empresa não recebe o teste de perfil sem a autorização dele.
... A18: 14 | B18: Áudio no WhatsApp para fazer o currículo falando | C18: A pessoa manda áudios e recebe o currículo pronto. | D18: O currículo e as vagas que combinam. | E18: Aceite no começo da conversa. | F18: Verificar (transcrição e mensagens) | G18: Muito | H18: Não | I18: O áudio é dado pessoal: apagar depois de transcrever.
B20: Canais prontos para 13/10 | C20: =COUNTIF(H5:H18,"Sim") -> 3
B21: Parcialmente prontos | C21: =COUNTIF(H5:H18,"Parcial") -> 3
B22: Total de canais | C22: =COUNTA(B5:B18) -> 14
B24: O que o painel do dono mostra todo dia | C24: Para quê
B25: Pessoas que entraram hoje, por canal | C25: Saber qual canal funciona e onde parar de gastar.
B26: Quantas aceitaram receber avisos | C26: O banco útil é o que tem aceite.
B27: Quantas já têm currículo e quantas fizeram teste | C27: Medir se o cadastro vira perfil completo.
B28: Quantas fizeram a lição do dia e quantas voltaram | C28: Medir o hábito, que mantém o banco vivo.
B29: Vagas novas e candidatos por vaga | C29: Equilibrar os dois lados.
B30: Tempo até a primeira resposta de uma empresa | C30: Candidato sem resposta some do app.
B31: Matrículas e comissões do mês | C31: Acompanhar a receita das parcerias.

Sheet Sistema vivo
A1: Sistema vivo: agentes que propõem melhoria todo dia, e pessoas que decidem
A2: Agente propõe, gente decide. Nada vai ao ar sem os testes passarem e sem o GD aprovar a mudança.
A4: Agente | B4: O que faz | C4: Quando roda | D4: O que entrega | E4: Quem aprova | F4: Cuidado
A5: Benchmark | B5: Olha o que os concorrentes e o mercado de RH e de educação lançaram de novo e compara com o que temos. | C5: Toda semana | D5: Relatório curto com 3 ideias e o que custa fazer cada uma. | E5: GD | F5: Só informação pública; sem entrar em conta de ninguém.
A6: Cursos | B6: Vê onde os alunos erram e onde abandonam e propõe versão melhor do curso. | C6: Toda semana | D6: Lição reescrita e perguntas novas. | E6: Revisor humano | F6: A IA pode errar conteúdo: revisão antes de publicar.
A7: Vídeos | B7: Faz roteiro de vídeo curto a partir de cada curso e dica de carreira. | C7: Toda semana | D7: Roteiro e legenda prontos. | E7: GD | F7: Nada que prometa emprego nem fale de pessoa real.
A8: Qualidade do match | B8: Compara a nota prevista com quem foi contratado de verdade. | C8: Todo mês | D8: Proposta de novos pesos, com o antes e o depois. | E8: GD e advogado | F8: Nunca muda o peso sozinho; sem usar dado sensível.
A9: Comunicação | B9: Testa horários e textos de mensagem para quem aceitou receber. | C9: Contínuo | D9: Qual texto trouxe mais gente de volta. | E9: GD | F9: Só para quem deu aceite; respeitar o pedido de sair.
A10: Parcerias | B10: Lembra as escolas de atualizar cursos e vagas e confere a conta de comissão do mês. | C10: Todo mês | D10: Extrato por escola e pendências. | E10: GD | F10: Divergência vai para análise, não vira cobrança automática.
A11: Privacidade | B11: Atende pedido de apagar ou corrigir dados e confere se o aceite está em dia. | C11: Todo dia | D11: Lista do que foi atendido. | E11: Automático, com revisão do advogado | F11: Prazos da lei (a confirmar).
A12: Saúde do sistema | B12: Confere cópia de segurança, atualização e velocidade. | C12: Todo dia | D12: Aviso só se algo estiver errado. | E12: Automático | F12: Atualização automática com volta atrás é decisão pendente do GD.
A13: Currículos | B13: Vê se os modelos continuam sendo lidos pelos programas das empresas e propõe novos. | C13: Todo mês | D13: Modelos ajustados e testes. | E13: GD | F13: A nota de leitura automática hoje é nossa avaliação.
A15: Limites: cada agente tem teto de custo por mês (a definir) e só mexe no que está descrito. Mudança de código passa por pull request, testes e o seu aceite.

Sheet IA para o dono
A1: IA para cada dono que comprar o software: 3 pilares, por voz ou foto
A2: Benchmark do texto da V4 (colado pelo GD): conteúdo em escala, análise de dados e imagens profissionais. Aqui, como isso vira função em cada produto.
A4: Pilar | B4: O que o dono pede | C4: No Vem Comer | D4: No Vem Trabalhar | E4: Em cursos e currículo | F4: Regra de segurança | G4: Situação hoje
A5: 1. Conteúdo em escala: uma ideia vira 10 formatos | B5: 'Faz um post desse prato.' 'Divulga essa vaga.' | C5: Do prato saem: post, carrossel, story, texto de WhatsApp, cartaz com QR, roteiro de vídeo curto, e-mail, promoção, legenda e mensagem de aniversário. | D5: Da vaga saem: post, story, texto de WhatsApp, cartaz com QR, e-mail e vídeo curto, prontos para as páginas de vagas do Instagram. | E5: De uma lição saem vídeo curto, post e quiz. Do currículo sai a mensagem de apresentação para o WhatsApp. | F5: O dono aprova antes de publicar. Nada que prometa o que o negócio não entrega. Vaga nunca promete salário que não está cadastrado. | G5: A fazer
A6: 2. Analisar dados e decidir mais rápido | B6: 'Como foi a semana?' 'Onde estou perdendo dinheiro?' | C6: Prato com margem baixa (custo e CMV), desperdício, horário vazio, prato que não vende, preço fora do padrão. | D6: Vaga parada, candidatos por vaga, onde a nota perde pontos, tempo até a primeira resposta, saída de funcionários. | E6: Onde o aluno erra e onde desiste do curso. | F6: Todo número mostra de onde vem. A sugestão é sugestão: o dono decide. Resposta curta, em linguagem simples. | G6: A fazer (CMV é o item 6 e alertas o item 10 da ordem de trabalho)
A7: 3. Imagens profissionais | B7: 'Melhora essa foto.' 'Faz a logomarca.' 'Faz o cartaz da vaga.' | C7: Foto do prato melhorada a partir da foto real, com fundo limpo; logomarca; banner do cardápio. | D7: Imagem da vaga e cartaz com QR; capa de curso. | E7: Currículo sem foto de pessoa criada por IA. | F7: Foto de prato só melhora a real. Imagem criada do zero leva o aviso 'imagem ilustrativa' (o cliente não pode ser enganado sobre o que recebe; advogado confere o Código de Defesa do Consumidor). Nunca criar pessoa que não existe em currículo ou depoimento. | G7: Parcial: foto do cardápio pronta (falta a chave de IA e teste com cardápios reais); logomarca pronta (aguarda o seu merge)
A8: 4. Gestão por voz e por foto | B8: Falar ou mandar foto, em vez de digitar | C8: Ver a aba Comandos de voz. | D8: Ver a aba Comandos de voz. | E8: Ver a aba Entrevista do currículo. | F8: Ação que mexe com dinheiro, preço ou apaga algo sempre pede confirmação lida em voz alta, e pode ser desfeita. | G8: A fazer
A9: 5. Muitas empresas na mesma plataforma | B9: 'Cada cliente meu com a sua marca.' | C9: Cada restaurante isolado, com logomarca, cores e cardápio próprios. | D9: Cada empresa isolada, com vagas e candidatos próprios. | E9: Cada empresa vê só os seus funcionários e resultados. | F9: Uma empresa nunca enxerga dado de outra. O dono da plataforma enxerga números gerais, não o conteúdo de cada uma. | G9: Isolamento por empresa já existe. Logomarca pronta. Faltam domínio próprio e teste de Pix de R$ 1.

Sheet Comandos de voz
A1: Comandos de voz e de foto: o dono fala, o sistema faz
A2: Frases de exemplo. O sistema entende o jeito de falar de cada pessoa; estas servem para desenhar e testar.
A4: Nº | B4: Produto | C4: Quem fala | D4: O que diz | E4: O que o sistema faz | F4: Pede confirmação? | G4: Cuidado
A5: 1 | B5: Vem Comer | C5: Dono ou gerente | D5: Quanto eu vendi hoje? | E5: Lê as vendas, os pedidos e o ticket médio do dia. | F5: Não | G5: Número vem do sistema, com a hora da última atualização.
A6: 2 | B6: Vem Comer | C6: Dono ou gerente | D6: Qual prato vende mais esta semana? | E6: Lista os 5 mais vendidos e os 5 que menos saem. | F6: Não | G6: -
A7: 3 | B7: Vem Comer | C7: Dono ou gerente | D7: Coloca o prato frango com batata por R$ 25. | E7: Cria ou muda o produto e mostra o preço escrito. | F7: Sim | G7: Lê o preço em voz alta antes de salvar.
A8: 4 | B8: Vem Comer | C8: Dono ou gerente | D8: Tira o prato X do cardápio por hoje. | E8: Pausa o prato até a meia-noite. | F8: Sim | G8: Volta sozinho no dia seguinte.
A9: 5 | B9: Vem Comer | C9: Dono ou gerente | D9: Aumenta as bebidas em 10 por cento. | E9: Mostra a lista com o preço novo de cada bebida. | F9: Sim | G9: Aplica só depois do toque em 'confirmar'; tem 'desfazer'.
A10: 6 | B10: Vem Comer | C10: Dono ou gerente | D10: (manda uma foto de um prato) Esse é o prato do dia. | E10: Melhora a foto, cria o prato e pede o preço e a descrição. | F10: Sim | G10: Só melhora a foto real.
A11: 7 | B11: Vem Comer | C11: Dono ou gerente | D11: Faz um post desse prato. | E11: Gera post, story e texto de WhatsApp para aprovar. | F11: Sim | G11: Nada é publicado sem o dono aprovar.
A12: 8 | B12: Vem Comer | C12: Dono ou gerente | D12: Onde eu estou perdendo dinheiro? | E12: Mostra os 3 maiores vazamentos com o valor de cada um. | F12: Não | G12: Diz de onde vem cada número.
A13: 9 | B13: Vem Comer | C13: Garçom | D13: Mesa 5 quer mais uma água e um suco de laranja. | E13: Lança os itens na mesa 5. | F13: Sim | G13: Garçom não muda preço.
A14: 10 | B14: Vem Comer | C14: Caixa | D14: Fecha a mesa 3 no Pix. | E14: Fecha a conta e mostra o QR. | F14: Sim | G14: Só o caixa fecha.
A15: 11 | B15: Vem Comer | C15: Cozinha | D15: Pedido 12 está pronto. | E15: Marca como pronto e avisa o garçom. | F15: Não | G15: -
A16: 12 | B16: Vem Comer | C16: Dono ou gerente | D16: Cria uma promoção de almoço de segunda a sexta. | E16: Monta a promoção e o cartaz para aprovar. | F16: Sim | G16: Mostra o preço final antes de ligar.
... A36: 32 | B36: Dono da plataforma | C36: GD | D36: Quanto as escolas devem de comissão? | E36: Mostra o extrato por escola. | F36: Não | G36: Aba Portal do parceiro.
B38: Comandos | C38: =COUNTA(D5:D36) -> 32
B39: Pedem confirmação | C39: =COUNTIF(F5:F36,"Sim*") -> 13
B41: O reconhecimento de voz do celular pode precisar de internet; a verificar como fica em 2G. Se não houver rede, o sistema oferece os botões de toque.

Sheet Benchmark
A1: Benchmark: o que vimos de novo e onde entra
A2: O agente de benchmark da aba Sistema vivo acrescenta linhas aqui. A coluna amarela é a sua decisão.
A4: Data | B4: Onde vimos | C4: O que vimos | D4: O que serve para nós | E4: Onde entra | F4: Prioridade | G4: Decisão do GD
A5: 06/10/2026 | B5: Texto de uma empresa chamada V4 (colado pelo GD) | C5: Quem não usa IA em 3 coisas fica para trás: 1) conteúdo em escala, uma ideia vira 10 formatos; 2) análise de dados e decisão mais rápida; 3) imagens profissionais sem sessão de fotos. | D5: Os três pilares viram o que cada dono recebe, por voz ou foto (aba IA para o dono). | E5: Vem Comer, Vem Trabalhar, cursos, currículo | F5: Alta
A6: 06/10/2026 | B6: Anúncio no Instagram (print do GD): gentia.tech, '50 vagas rodando para 1 recrutador' | C6: Promessa de um recrutador dar conta de 50 vagas com IA. | D6: A lista ordenada com o motivo da nota e o match de 20 perguntas atacam a mesma dor. | E6: Vem Trabalhar | F6: Alta
A7: 06/10/2026 | B7: Sites de RH que o GD já viu (um anotado como 'Holdings Group'; o nome pode ser erro de transcrição) | C7: Segundo o GD, nenhum atende do autônomo até a empresa de mil funcionários com uma ideia só. É afirmação do GD; eu não verifiquei esses sites. | D7: O nosso diferencial: o mesmo método, as mesmas telas, qualquer tamanho de empresa. | E7: Vem Trabalhar | F7: Alta

Sheet Prioridade
A1: Prioridade de cursos por região e setor
A2: Alta, Média ou Baixa. É avaliação nossa, sem dados; toque na célula para mudar. A aba Ideias de cursos lê esta tabela.
A4: Região | B4: Indústria | C4: Agro | D4: Técnico e tecnologia | E4: Turismo e gastronomia | F4: Comércio e serviços | G4: Gestão e carreira | H4: Transporte e logística | I4: Saúde e cuidados | J4: Construção
A5: Norte | B5: Alta | C5: Média | D5: Alta | E5: Média | F5: Média | G5: Alta | H5: Média | I5: Média | J5: Média
A6: Nordeste | B6: Média | C6: Alta | D6: Média | E6: Alta | F6: Alta | G6: Alta | H6: Média | I6: Média | J6: Média
A7: Centro-Oeste | B7: Média | C7: Alta | D7: Média | E7: Média | F7: Média | G7: Alta | H7: Alta | I7: Média | J7: Média
A8: Sudeste | B8: Alta | C8: Média | D8: Alta | E8: Média | F8: Alta | G8: Alta | H8: Alta | I8: Média | J8: Média
A9: Sul | B9: Alta | C9: Alta | D9: Alta | E9: Média | F9: Média | G9: Alta | H9: Alta | I9: Média | J9: Média
A12: Setor | B12: De onde vem a avaliação
A13: Indústria | B13: Avaliação nossa: polo de Manaus no Norte, indústria forte no Sudeste e no Sul.
A14: Agro | B14: Avaliação nossa: soja no Centro-Oeste, agropecuária no Sul, cana e pecuária no Nordeste.
A15: Técnico e tecnologia | B15: Avaliação nossa: eletroeletrônica no Norte, energia eólica no Nordeste, serviços no Sudeste.
A16: Turismo e gastronomia | B16: Avaliação nossa: o Nordeste é o destino mais procurado nas viagens de verão.
A17: Comércio e serviços | B17: Avaliação nossa: serviços pesam em todas as regiões.
A18: Gestão e carreira | B18: Transversal: vale para todas as regiões.
A19: Transporte e logística | B19: Avaliação nossa, ligada ao escoamento da safra e da indústria.
A20: Saúde e cuidados | B20: Avaliação nossa, sem dado ainda: todas Média.
A21: Construção | B21: Avaliação nossa, sem dado ainda: todas Média.

Sheet Matching
A1: Matching: 20 perguntas ao candidato e 20 correspondentes na vaga
A2: Cada pergunta do candidato tem a sua gêmea na vaga. A regra diz como comparar (nota de 0 a 1) e o peso diz quanto vale. Pesos são ponto de partida: letra azul, pode mudar.
A4: Nº | B4: Bloco | C4: Tema | D4: Pergunta ao candidato (toque ou voz) | E4: Respostas do candidato | F4: Pergunta na vaga (empresa) | G4: Respostas da empresa | H4: Como compara (nota de 0 a 1) | I4: Se não combinar | J4: Peso (1 a 5)
A5: 1 | B5: A. Logística | C5: Local e deslocamento | D5: Onde você mora? E quanto tempo aceita gastar para chegar ao trabalho? Como você vai? | E5: Localização (CEP ou 'usar onde estou'); tempo: 15 / 30 / 45 / 60 / 90 min ou mais; meio: a pé, bicicleta, moto, ônibus, carro. | F5: Onde fica o posto de trabalho? A empresa dá transporte ou vale-transporte? | G5: CEP do local; transporte da empresa: sim / não; vale-transporte: sim / não. | H5: Tempo estimado de casa ao trabalho no meio escolhido (aba Geografia). Dentro do limite = 1; até 20% acima = 0,5; acima = 0. | I5: Filtro do candidato | J5: 5
A6: 2 | B6: A. Logística | C6: Modalidade | D6: Onde prefere trabalhar? (pode marcar mais de uma) | E6: Presencial; híbrido; de casa. | F6: A vaga é presencial, híbrida ou remota? | G6: Presencial; híbrida; remota. | H6: Vaga dentro do que a pessoa aceita = 1; híbrido contra presencial ou remoto = 0,5; fora = 0. | I6: Filtro do candidato | J6: 4
A7: 3 | B7: A. Logística | C7: Turno e escala | D7: Em quais turnos você pode trabalhar? | E7: Manhã; tarde; noite; madrugada; fins de semana; feriados; escala 12x36. | F7: Qual o turno e a escala da vaga? | G7: Os mesmos turnos, mais escala 12x36 e carga semanal. | H7: Todos os turnos da vaga cobertos = 1; parte coberta = 0,5; nenhum = 0. | I7: Filtro do candidato | J7: 5
A8: 4 | B8: A. Logística | C8: Tipo de contrato | D8: Que tipo de contrato você aceita? | E8: CLT; estágio; jovem aprendiz; temporário; diária ou freelancer; MEI ou PJ. | F8: Qual o tipo de contrato? | G8: CLT; estágio; jovem aprendiz; temporário; diária ou freelancer; MEI ou PJ. | H8: Contrato aceito pela pessoa = 1; senão 0. | I8: Filtro do candidato | J8: 4
A9: 5 | B9: A. Logística | C9: Salário e benefícios | D9: Quanto você precisa ganhar por mês? | E9: Faixas de toque (a combinar, ou escolher a faixa); benefícios que importam: vale-transporte, refeição, plano de saúde. | F9: Qual a faixa de salário e os benefícios? | G9: Faixa de salário; benefícios: vale-transporte, refeição, plano, comissão. | H9: Faixas se encontram = 1; vaga até 10% abaixo do que a pessoa precisa = 0,5; mais que isso = 0. | I9: Filtro do candidato | J9: 5
A10: 6 | B10: A. Logística | C10: Quando começar | D10: Quando você pode começar? | E10: Já; em 15 dias; em 30 dias; depois. | F10: Para quando a vaga precisa de alguém? | G10: Urgente; em 15 dias; em 30 dias; sem pressa. | H10: Pessoa começa até a data pedida = 1; atraso de até 15 dias = 0,5; mais = 0. | I10: Só pontua | J10: 2
A11: 7 | B11: A. Logística | C11: Estudo junto com o trabalho | D11: Quer estudar junto com o trabalho? Como? | E11: Não; a distância (EAD); presencial; os dois. Horários livres para estudar. | F11: A empresa apoia o estudo? | G11: Não; horário flexível; paga curso ou bolsa; tem curso interno. | H11: Quer estudar e a empresa apoia = 1; tanto faz = 0,5; querem coisas opostas = 0. Se o curso é presencial, entra a distância casa, estudo e trabalho (aba Geografia). | I11: Só pontua | J11: 2
A12: 8 | B12: B. Função e preparo | C12: Função desejada | D12: Que tipo de trabalho você procura? (fale ou escolha até 3) | E12: Busca por voz ou lista de ocupações, agrupada por área. | F12: Qual a função da vaga? | G12: A mesma lista de ocupações. | H12: Mesma função = 1; função da mesma família = 0,6; mesma área = 0,3; outra = 0. | I12: Só pontua | J12: 5
A13: 9 | B13: B. Função e preparo | C13: Experiência | D13: Quanto tempo de experiência você tem nessa função? | E13: Nenhuma; até 1 ano; 1 a 3 anos; 3 a 5 anos; mais de 5 anos. | F13: Qual experiência a vaga exige? A empresa treina quem não tem? | G13: Nenhuma; até 1 ano; 1 a 3; 3 a 5; mais de 5. Marcar 'treinamos'. | H13: Experiência igual ou maior = 1; um nível abaixo = 0,5; mais abaixo = 0. Se a empresa marcou 'treinamos', quem não tem experiência pontua 0,8. Primeiro emprego nunca é penalizado em vaga que aceita sem experiência. | I13: Obrigatória só se a empresa marcar | J13: 4
A14: 10 | B14: B. Função e preparo | C14: Escolaridade | D14: Até onde você estudou? | E14: Fundamental incompleto ou completo; médio incompleto ou completo; técnico; superior cursando ou completo; pós. | F14: Qual a escolaridade mínima? | G14: A mesma escala, mais 'aceita quem está cursando'. | H14: Nível igual ou maior = 1; cursando e a vaga aceita = 0,7; um nível abaixo = 0,4; mais abaixo = 0. | I14: Obrigatória só se a empresa marcar | J14: 3
A15: 11 | B15: B. Função e preparo | C15: Habilidades | D15: Marque até 5 coisas que você faz bem. | E15: Lista por área (atender, vender, cozinhar, operar caixa, organizar estoque, dirigir, consertar, desenhar, ensinar...). | F15: Marque até 5 habilidades essenciais para a vaga. | G15: A mesma lista. | H15: Quantas das habilidades da vaga a pessoa tem, dividido pelo total da vaga. | I15: Só pontua | J15: 5
A16: 12 | B16: B. Função e preparo | C16: Ferramentas e equipamentos | D16: Quais máquinas, programas ou equipamentos você sabe usar? | E16: Lista por área (caixa e maquininha, Excel, empilhadeira, forno, furadeira, WhatsApp comercial...). | F16: O que a pessoa vai usar no dia a dia? | G16: A mesma lista. | H16: Quantas das ferramentas da vaga a pessoa conhece, dividido pelo total. | I16: Só pontua | J16: 3
... A24: 20 | B24: C. Jeito de trabalhar | C24: Crescimento | D24: O que você busca agora? | E24: Aprender uma profissão; crescer na empresa; estabilidade; renda extra. | F24: O que a empresa oferece? | G24: Treinamento; plano de carreira; efetivação; renda extra. | H24: Igual = 1; parcial = 0,5; sem relação = 0. | I24: Só pontua | J24: 2
C25: Perguntas | D25: =COUNTA(C5:C24) -> 20
C26: Soma dos pesos | D26: =SUM(J5:J24) -> 68
C28: Filtro do candidato: a vaga some da lista dele quando contraria um 'não' que ele mesmo marcou. Quem decide é ele, não o sistema.
C29: Obrigatória só se a empresa marcar: a empresa pode marcar até 3 perguntas como obrigatórias. Quem não atende aparece com o aviso 'não atende' e a empresa decide se abre ou não. Nada é escondido da empresa nem descartado sozinho.
C30: Dado que a empresa deixa em branco não entra na conta (o peso daquele par sai do total).
C31: Sinal 21, opcional: o teste de jeito de ser (aba Perfil) só entra se a pessoa autorizar e a empresa pedir. Nunca elimina.
C32: A pessoa vê a nota, os 3 pares que mais tiraram pontos e o curso que melhoraria cada um.
C33: Raça, religião, estado civil, filhos, idade, foto e saúde não fazem parte de nenhum par.

Sheet Matching exemplo
A1: Exemplo de nota do matching (candidato e vaga inventados)
A2: Candidata de exemplo: procura balcão ou caixa, tem 1 ano de experiência, aceita CLT, pode à tarde e à noite. Vaga: atendente de padaria. Troque os números amarelos para ver a nota mudar.
B4: Obrigatória não atende abaixo de | C4: 0.5
B5: Faixa 'Muito boa' a partir de | C5: 0.8
B6: Faixa 'Boa' a partir de | C6: 0.6
B7: Faixa 'Possível' a partir de | C7: 0.4
A9: Nº | B9: Tema | C9: Peso | D9: Aplica? | E9: Nota (0 a 1) | F9: Obrigatória? | G9: Pontos | H9: Peso usado | I9: Perda (aux.) | J9: Alerta
A10: 1 | B10: =Matching!C5 -> Local e deslocamento | C10: =Matching!J5 -> 5 | D10: Sim | E10: 1 | F10: Não | G10: =IF(D10="Sim",C10*E10,0) -> 5 | H10: =IF(D10="Sim",C10,0) -> 5 | I10: =IF(D10="Sim",C10*(1-E10),0)+ROW()/1000000 -> 1e-05 | J10: =IF(AND(D10="Sim",F10="Sim",E10<$C$4),"Não atende","") | L10: Nota do match | M10: =IF(SUM(H10:H29)=0,"",SUM(G10:G29)/SUM(H10:H29)) -> 0.78225806
A11: 2 | B11: =Matching!C6 -> Modalidade | C11: =Matching!J6 -> 4 | D11: Sim | E11: 1 | F11: Não | G11: =IF(D11="Sim",C11*E11,0) -> 4 | H11: =IF(D11="Sim",C11,0) -> 4 | I11: =IF(D11="Sim",C11*(1-E11),0)+ROW()/1000000 -> 1.1e-05 | J11: =IF(AND(D11="Sim",F11="Sim",E11<$C$4),"Não atende","") | L11: Faixa | M11: =IF(M10="","",IF(M10>=$C$5,"Muito boa",IF(M10>=$C$6,"Boa",IF(M10>=$C$7,"Possível","Distante")))) -> Boa
A12: 3 | B12: =Matching!C7 -> Turno e escala | C12: =Matching!J7 -> 5 | D12: Sim | E12: 1 | F12: Não | G12: =IF(D12="Sim",C12*E12,0) -> 5 | H12: =IF(D12="Sim",C12,0) -> 5 | I12: =IF(D12="Sim",C12*(1-E12),0)+ROW()/1000000 -> 1.2e-05 | J12: =IF(AND(D12="Sim",F12="Sim",E12<$C$4),"Não atende","") | L12: Atende todas as obrigatórias? | M12: =IF(COUNTIF(J10:J29,"Não atende")=0,"Sim","Não") -> Sim
A13: 4 | B13: =Matching!C8 -> Tipo de contrato | C13: =Matching!J8 -> 4 | D13: Sim | E13: 1 | F13: Não | G13: =IF(D13="Sim",C13*E13,0) -> 4 | H13: =IF(D13="Sim",C13,0) -> 4 | I13: =IF(D13="Sim",C13*(1-E13),0)+ROW()/1000000 -> 1.3e-05 | J13: =IF(AND(D13="Sim",F13="Sim",E13<$C$4),"Não atende","")
A14: 5 | B14: =Matching!C9 -> Salário e benefícios | C14: =Matching!J9 -> 5 | D14: Sim | E14: 0.5 | F14: Não | G14: =IF(D14="Sim",C14*E14,0) -> 2.5 | H14: =IF(D14="Sim",C14,0) -> 5 | I14: =IF(D14="Sim",C14*(1-E14),0)+ROW()/1000000 -> 2.500014 | J14: =IF(AND(D14="Sim",F14="Sim",E14<$C$4),"Não atende","") | L14: Onde mais perdeu pontos (mostrar à pessoa)
A15: 6 | B15: =Matching!C10 -> Quando começar | C15: =Matching!J10 -> 2 | D15: Sim | E15: 1 | F15: Não | G15: =IF(D15="Sim",C15*E15,0) -> 2 | H15: =IF(D15="Sim",C15,0) -> 2 | I15: =IF(D15="Sim",C15*(1-E15),0)+ROW()/1000000 -> 1.5e-05 | J15: =IF(AND(D15="Sim",F15="Sim",E15<$C$4),"Não atende","") | L15: =IF(LARGE($I$10:$I$29,1)<0.001,"",INDEX($B$10:$B$29,MATCH(LARGE($I$10:$I$29,1),$I$10:$I$29,0))) -> Habilidades
A16: 7 | B16: =Matching!C11 -> Estudo junto com o trabalho | C16: =Matching!J11 -> 2 | D16: Sim | E16: 0.5 | F16: Não | G16: =IF(D16="Sim",C16*E16,0) -> 1 | H16: =IF(D16="Sim",C16,0) -> 2 | I16: =IF(D16="Sim",C16*(1-E16),0)+ROW()/1000000 -> 1.000016 | J16: =IF(AND(D16="Sim",F16="Sim",E16<$C$4),"Não atende","") | L16: =IF(LARGE($I$10:$I$29,2)<0.001,"",INDEX($B$10:$B$29,MATCH(LARGE($I$10:$I$29,2),$I$10:$I$29,0))) -> Salário e benefícios
